<?xml version="1.0" ?>
<!-- =================================================================================== -->
<!-- |    This document was autogenerated by xacro from right_robotiq_gripper_3_finger_adaptive.xacro | -->
<!-- |    EDITING THIS FILE BY HAND IS NOT RECOMMENDED                                 | -->
<!-- =================================================================================== -->
<robot name="right_robotiq_gripper_3_finger_adaptive" xmlns:xacro="http://www.ros.org/wiki/xacro">
  <link name="right_gripper_base_link">
    <visual>
      <origin rpy="0 0 0" xyz="0 0 0"/>
      <geometry>
        <mesh filename="package://robotiq_gripper_3_finger_adaptive_support/meshes/gripper_base_link.STL"/>
      </geometry>
      <material name="">
        <color rgba="0.10196 0.10196 0.10196 1"/>
      </material>
    </visual>
    <collision>
      <origin rpy="0 0 0" xyz="0 0 0"/>
      <geometry>
        <mesh filename="package://robotiq_gripper_3_finger_adaptive_support/meshes/gripper_base_link.STL"/>
      </geometry>
    </collision>
  </link>
  <link name="right_gripper_finger_link_a_1">
    <visual>
      <origin rpy="0 0 0" xyz="0 0 0"/>
      <geometry>
        <mesh filename="package://robotiq_gripper_3_finger_adaptive_support/meshes/gripper_finger_link_1.STL"/>
      </geometry>
      <material name="">
        <color rgba="0.10196 0.10196 0.10196 1"/>
      </material>
    </visual>
    <collision>
      <origin rpy="0 0 0" xyz="0 0 0"/>
      <geometry>
        <mesh filename="package://robotiq_gripper_3_finger_adaptive_support/meshes/gripper_finger_link_1.STL"/>
      </geometry>
    </collision>
  </link>
  <joint name="right_gripper_finger_joint_a_1" type="revolute">
    <origin rpy="1.57079632679 0.0079495 -3.0107" xyz="0.044008 -0.054539 0.13897"/>
    <parent link="right_gripper_base_link"/>
    <child link="right_gripper_finger_link_a_1"/>
    <axis xyz="0 0 -1"/>
    <limit effort="1000" lower="-0.1755" upper="0.1744" velocity="0.1744"/>
  </joint>
  <link name="right_gripper_finger_link_a_2">
    <visual>
      <origin rpy="0 0 0" xyz="0 0 0"/>
      <geometry>
        <mesh filename="package://robotiq_gripper_3_finger_adaptive_support/meshes/gripper_finger_link_2.STL"/>
      </geometry>
      <material name="">
        <color rgba="0.10196 0.10196 0.10196 1"/>
      </material>
    </visual>
    <collision>
      <origin rpy="0 0 0" xyz="0 0 0"/>
      <geometry>
        <mesh filename="package://robotiq_gripper_3_finger_adaptive_support/meshes/gripper_finger_link_2.STL"/>
      </geometry>
    </collision>
  </link>
  <joint name="right_gripper_finger_joint_a_2" type="revolute">
    <origin rpy="3.14159265359 -1.57079632679 3.14159265359" xyz="0.011219 0.021604 0.014288"/>
    <parent link="right_gripper_finger_link_a_1"/>
    <child link="right_gripper_finger_link_a_2"/>
    <axis xyz="0 0 -1"/>
    <limit effort="1000" lower="0" upper="1.4801" velocity="1.4801"/>
  </joint>
  <link name="right_gripper_finger_link_a_3">
    <visual>
      <origin rpy="0 0 0" xyz="0 0 0"/>
      <geometry>
        <mesh filename="package://robotiq_gripper_3_finger_adaptive_support/meshes/gripper_finger_link_3.STL"/>
      </geometry>
      <material name="">
        <color rgba="0.10196 0.10196 0.10196 1"/>
      </material>
    </visual>
    <collision>
      <origin rpy="0 0 0" xyz="0 0 0"/>
      <geometry>
        <mesh filename="package://robotiq_gripper_3_finger_adaptive_support/meshes/gripper_finger_link_3.STL"/>
      </geometry>
    </collision>
  </link>
  <joint name="right_gripper_finger_joint_a_3" type="revolute">
    <origin rpy="0 0 -0.05236" xyz="-0.03278 0.046815 -0.0007872"/>
    <parent link="right_gripper_finger_link_a_2"/>
    <child link="right_gripper_finger_link_a_3"/>
    <axis xyz="0 0 -1"/>
    <limit effort="1000" lower="0" upper="1.2322" velocity="1.2322"/>
  </joint>
  <link name="right_gripper_finger_link_a_4">
    <visual>
      <origin rpy="0 0 0" xyz="0 0 0"/>
      <geometry>
        <mesh filename="package://robotiq_gripper_3_finger_adaptive_support/meshes/gripper_finger_link_4.STL"/>
      </geometry>
      <material name="">
        <color rgba="0.10196 0.10196 0.10196 1"/>
      </material>
    </visual>
    <collision>
      <origin rpy="0 0 0" xyz="0 0 0"/>
      <geometry>
        <mesh filename="package://robotiq_gripper_3_finger_adaptive_support/meshes/gripper_finger_link_4.STL"/>
      </geometry>
    </collision>
  </link>
  <joint name="right_gripper_finger_joint_a_4" type="revolute">
    <origin rpy="0 0 0.05236" xyz="-0.021853 0.03121 1.28E-05"/>
    <parent link="right_gripper_finger_link_a_3"/>
    <child link="right_gripper_finger_link_a_4"/>
    <axis xyz="0 0 -1"/>
    <limit effort="1000" lower="-1.27" upper="0.6757" velocity="0.6757"/>
  </joint>
  <link name="right_gripper_finger_link_b_1">
    <visual>
      <origin rpy="0 0 0" xyz="0 0 0"/>
      <geometry>
        <mesh filename="package://robotiq_gripper_3_finger_adaptive_support/meshes/gripper_finger_link_1.STL"/>
      </geometry>
      <material name="">
        <color rgba="0.10196 0.10196 0.10196 1"/>
      </material>
    </visual>
    <collision>
      <origin rpy="0 0 0" xyz="0 0 0"/>
      <geometry>
        <mesh filename="package://robotiq_gripper_3_finger_adaptive_support/meshes/gripper_finger_link_1.STL"/>
      </geometry>
    </collision>
  </link>
  <joint name="right_gripper_finger_joint_b_1" type="revolute">
    <origin rpy="1.57079632679 0.0079495 -3.0107" xyz="-0.028392 -0.064071 0.13897"/>
    <parent link="right_gripper_base_link"/>
    <child link="right_gripper_finger_link_b_1"/>
    <axis xyz="0 0 1"/>
    <limit effort="1000" lower="-0.1755" upper="0.1744" velocity="0.1744"/>
  </joint>
  <link name="right_gripper_finger_link_b_2">
    <visual>
      <origin rpy="0 0 0" xyz="0 0 0"/>
      <geometry>
        <mesh filename="package://robotiq_gripper_3_finger_adaptive_support/meshes/gripper_finger_link_2.STL"/>
      </geometry>
      <material name="">
        <color rgba="0.10196 0.10196 0.10196 1"/>
      </material>
    </visual>
    <collision>
      <origin rpy="0 0 0" xyz="0 0 0"/>
      <geometry>
        <mesh filename="package://robotiq_gripper_3_finger_adaptive_support/meshes/gripper_finger_link_2.STL"/>
      </geometry>
    </collision>
  </link>
  <joint name="right_gripper_finger_joint_b_2" type="revolute">
    <origin rpy="3.14159265359 -1.57079632679 3.14159265359" xyz="0.011219 0.021604 0.014288"/>
    <parent link="right_gripper_finger_link_b_1"/>
    <child link="right_gripper_finger_link_b_2"/>
    <axis xyz="0 0 -1"/>
    <limit effort="1000" lower="0" upper="1.4801" velocity="1.4801"/>
  </joint>
  <link name="right_gripper_finger_link_b_3">
    <visual>
      <origin rpy="0 0 0" xyz="0 0 0"/>
      <geometry>
        <mesh filename="package://robotiq_gripper_3_finger_adaptive_support/meshes/gripper_finger_link_3.STL"/>
      </geometry>
      <material name="">
        <color rgba="0.10196 0.10196 0.10196 1"/>
      </material>
    </visual>
    <collision>
      <origin rpy="0 0 0" xyz="0 0 0"/>
      <geometry>
        <mesh filename="package://robotiq_gripper_3_finger_adaptive_support/meshes/gripper_finger_link_3.STL"/>
      </geometry>
    </collision>
  </link>
  <joint name="right_gripper_finger_joint_b_3" type="revolute">
    <origin rpy="0 0 -0.05236" xyz="-0.03278 0.046815 -0.0007872"/>
    <parent link="right_gripper_finger_link_b_2"/>
    <child link="right_gripper_finger_link_b_3"/>
    <axis xyz="0 0 -1"/>
    <limit effort="1000" lower="0" upper="1.2322" velocity="1.2322"/>
  </joint>
  <link name="right_gripper_finger_link_b_4">
    <visual>
      <origin rpy="0 0 0" xyz="0 0 0"/>
      <geometry>
        <mesh filename="package://robotiq_gripper_3_finger_adaptive_support/meshes/gripper_finger_link_4.STL"/>
      </geometry>
      <material name="">
        <color rgba="0.10196 0.10196 0.10196 1"/>
      </material>
    </visual>
    <collision>
      <origin rpy="0 0 0" xyz="0 0 0"/>
      <geometry>
        <mesh filename="package://robotiq_gripper_3_finger_adaptive_support/meshes/gripper_finger_link_4.STL"/>
      </geometry>
    </collision>
  </link>
  <joint name="right_gripper_finger_joint_b_4" type="revolute">
    <origin rpy="0 0 0.05236" xyz="-0.021853 0.03121 1.28E-05"/>
    <parent link="right_gripper_finger_link_b_3"/>
    <child link="right_gripper_finger_link_b_4"/>
    <axis xyz="0 0 -1"/>
    <limit effort="1000" lower="-1.27" upper="0.6757" velocity="0.6757"/>
  </joint>
  <link name="right_gripper_finger_link_c_1">
    <visual>
      <origin rpy="0 0 0" xyz="0 0 0"/>
      <geometry>
        <mesh filename="package://robotiq_gripper_3_finger_adaptive_support/meshes/gripper_finger_link_1.STL"/>
      </geometry>
      <material name="">
        <color rgba="0.10196 0.10196 0.10196 1"/>
      </material>
    </visual>
    <collision>
      <origin rpy="0 0 0" xyz="0 0 0"/>
      <geometry>
        <mesh filename="package://robotiq_gripper_3_finger_adaptive_support/meshes/gripper_finger_link_1.STL"/>
      </geometry>
    </collision>
  </link>
  <joint name="right_gripper_finger_joint_c_1" type="fixed">
    <origin rpy="1.57079632679 0.0079495 0.1309" xyz="-0.007695 0.058449 0.13897"/>
    <parent link="right_gripper_base_link"/>
    <child link="right_gripper_finger_link_c_1"/>
    <axis xyz="0 0 0"/>
    <limit effort="1000" lower="0" upper="0" velocity="0"/>
  </joint>
  <link name="right_gripper_finger_link_c_2">
    <visual>
      <origin rpy="0 0 0" xyz="0 0 0"/>
      <geometry>
        <mesh filename="package://robotiq_gripper_3_finger_adaptive_support/meshes/gripper_finger_link_2.STL"/>
      </geometry>
      <material name="">
        <color rgba="0.10196 0.10196 0.10196 1"/>
      </material>
    </visual>
    <collision>
      <origin rpy="0 0 0" xyz="0 0 0"/>
      <geometry>
        <mesh filename="package://robotiq_gripper_3_finger_adaptive_support/meshes/gripper_finger_link_2.STL"/>
      </geometry>
    </collision>
  </link>
  <joint name="right_gripper_finger_joint_c_2" type="revolute">
    <origin rpy="3.14159265359 -1.57079632679 3.14159265359" xyz="0.011219 0.021604 0.014288"/>
    <parent link="right_gripper_finger_link_c_1"/>
    <child link="right_gripper_finger_link_c_2"/>
    <axis xyz="0 0 -1"/>
    <limit effort="1000" lower="0" upper="1.4801" velocity="1.4801"/>
  </joint>
  <link name="right_gripper_finger_link_c_3">
    <visual>
      <origin rpy="0 0 0" xyz="0 0 0"/>
      <geometry>
        <mesh filename="package://robotiq_gripper_3_finger_adaptive_support/meshes/gripper_finger_link_3.STL"/>
      </geometry>
      <material name="">
        <color rgba="0.10196 0.10196 0.10196 1"/>
      </material>
    </visual>
    <collision>
      <origin rpy="0 0 0" xyz="0 0 0"/>
      <geometry>
        <mesh filename="package://robotiq_gripper_3_finger_adaptive_support/meshes/gripper_finger_link_3.STL"/>
      </geometry>
    </collision>
  </link>
  <joint name="right_gripper_finger_joint_c_3" type="revolute">
    <origin rpy="0 0 -0.05236" xyz="-0.03278 0.046815 -0.0007872"/>
    <parent link="right_gripper_finger_link_c_2"/>
    <child link="right_gripper_finger_link_c_3"/>
    <axis xyz="0 0 -1"/>
    <limit effort="1000" lower="0" upper="1.2322" velocity="1.2322"/>
  </joint>
  <link name="right_gripper_finger_link_c_4">
    <visual>
      <origin rpy="0 0 0" xyz="0 0 0"/>
      <geometry>
        <mesh filename="package://robotiq_gripper_3_finger_adaptive_support/meshes/gripper_finger_link_4.STL"/>
      </geometry>
      <material name="">
        <color rgba="0.10196 0.10196 0.10196 1"/>
      </material>
    </visual>
    <collision>
      <origin rpy="0 0 0" xyz="0 0 0"/>
      <geometry>
        <mesh filename="package://robotiq_gripper_3_finger_adaptive_support/meshes/gripper_finger_link_4.STL"/>
      </geometry>
    </collision>
  </link>
  <joint name="right_gripper_finger_joint_c_4" type="revolute">
    <origin rpy="0 0 0.05236" xyz="-0.021853 0.03121 1.28E-05"/>
    <parent link="right_gripper_finger_link_c_3"/>
    <child link="right_gripper_finger_link_c_4"/>
    <axis xyz="0 0 -1"/>
    <limit effort="1000" lower="-1.27" upper="0.6757" velocity="0.6757"/>
  </joint>
</robot>

