<?xml version="1.0" ?>
<!-- =================================================================================== -->
<!-- |    This document was autogenerated by xacro from motoman_sda20d.xacro           | -->
<!-- |    EDITING THIS FILE BY HAND IS NOT RECOMMENDED                                 | -->
<!-- =================================================================================== -->
<robot name="motoman_sda20d" xmlns:xacro="http://www.ros.org/wiki/xacro">
  <link name="base_link">
    <visual>
      <origin rpy="0 0 0" xyz="0 0 0"/>
      <geometry>
        <mesh filename="package://motoman_sda20d_support/meshes/base_link.STL"/>
      </geometry>
      <material name="">
        <color rgba="0.79216 0.81 0.93 1"/>
      </material>
    </visual>
    <collision>
      <origin rpy="0 0 0" xyz="0 0 0"/>
      <geometry>
        <mesh filename="package://motoman_sda20d_support/meshes/base_link.STL"/>
      </geometry>
    </collision>
  </link>
  <link name="torso_link_b1">
    <visual>
      <origin rpy="0 0 0" xyz="0 0 0"/>
      <geometry>
        <mesh filename="package://motoman_sda20d_support/meshes/torso_link_b1.STL"/>
      </geometry>
      <material name="">
        <color rgba="0.79 0.81 1 1"/>
      </material>
    </visual>
    <collision>
      <origin rpy="0 0 0" xyz="0 0 0"/>
      <geometry>
        <mesh filename="package://motoman_sda20d_support/meshes/torso_link_b1.STL"/>
      </geometry>
    </collision>
  </link>
  <joint name="torso_joint_b1" type="revolute">
    <origin rpy="0 0 0" xyz="0 0 0.2765"/>
    <parent link="base_link"/>
    <child link="torso_link_b1"/>
    <axis xyz="0 0 1"/>
    <limit effort="1000" lower="-1.5555423498153687" upper="1.5555423498153687" velocity="2.4434"/>
  </joint>
  <link name="arm_left_link_s">
    <visual>
      <origin rpy="0 0 0" xyz="0 0 0"/>
      <geometry>
        <mesh filename="package://motoman_sda20d_support/meshes/arm_link_s.STL"/>
      </geometry>
      <material name="">
        <color rgba="0.79 0.81 0.93 1"/>
      </material>
    </visual>
    <collision>
      <origin rpy="0 0 0" xyz="0 0 0"/>
      <geometry>
        <mesh filename="package://motoman_sda20d_support/meshes/arm_link_s.STL"/>
      </geometry>
    </collision>
  </link>
  <joint name="arm_left_joint_s" type="revolute">
    <origin rpy="1.57079632679 -0.0 0" xyz="0.15 0.075 0.2984"/>
    <parent link="torso_link_b1"/>
    <child link="arm_left_link_s"/>
    <axis xyz="0 0 -1"/>
    <limit effort="1000" lower="-3.14" upper="3.14" velocity="0.9086"/>
  </joint>
  <link name="arm_left_link_l">
    <visual>
      <origin rpy="0 0 0" xyz="0 0 0"/>
      <geometry>
        <mesh filename="package://motoman_sda20d_support/meshes/arm_link_l.STL"/>
      </geometry>
      <material name="">
        <color rgba="0.79 0.81 1 1"/>
      </material>
    </visual>
    <collision>
      <origin rpy="0 0 0" xyz="0 0 0"/>
      <geometry>
        <mesh filename="package://motoman_sda20d_support/meshes/arm_link_l.STL"/>
      </geometry>
    </collision>
  </link>
  <joint name="arm_left_joint_l" type="revolute">
    <origin rpy="-1.57079632679 1.57079632679 0" xyz="0 -0.0571 -0.3145"/>
    <parent link="arm_left_link_s"/>
    <child link="arm_left_link_l"/>
    <axis xyz="0 0 -1"/>
    <limit effort="1000" lower="-1.92" upper="1.92" velocity="0.796"/>
  </joint>
  <link name="arm_left_link_e">
    <visual>
      <origin rpy="0 0 0" xyz="0 0 0"/>
      <geometry>
        <mesh filename="package://motoman_sda20d_support/meshes/arm_link_e.STL"/>
      </geometry>
      <material name="">
        <color rgba="0.79 0.81 0.93 1"/>
      </material>
    </visual>
    <collision>
      <origin rpy="0 0 0" xyz="0 0 0"/>
      <geometry>
        <mesh filename="package://motoman_sda20d_support/meshes/arm_link_e.STL"/>
      </geometry>
    </collision>
  </link>
  <joint name="arm_left_joint_e" type="revolute">
    <origin rpy="-1.57079632679 3.14159265359 1.57079632679" xyz="0.2659 0 0.04877"/>
    <parent link="arm_left_link_l"/>
    <child link="arm_left_link_e"/>
    <axis xyz="0 0 -1"/>
    <limit effort="1000" lower="-2.966" upper="2.966" velocity="1.039"/>
  </joint>
  <link name="arm_left_link_u">
    <visual>
      <origin rpy="0 0 0" xyz="0 0 0"/>
      <geometry>
        <mesh filename="package://motoman_sda20d_support/meshes/arm_link_u.STL"/>
      </geometry>
      <material name="">
        <color rgba="0.79 0.81 1 1"/>
      </material>
    </visual>
    <collision>
      <origin rpy="0 0 0" xyz="0 0 0"/>
      <geometry>
        <mesh filename="package://motoman_sda20d_support/meshes/arm_link_u.STL"/>
      </geometry>
    </collision>
  </link>
  <joint name="arm_left_joint_u" type="revolute">
    <origin rpy="1.57079632679 1.57079632679 0" xyz="0 0.0494 -0.2441"/>
    <parent link="arm_left_link_e"/>
    <child link="arm_left_link_u"/>
    <axis xyz="0 0 -1"/>
    <limit effort="1000" lower="-2.2689" upper="2.2689" velocity="1.188"/>
  </joint>
  <link name="arm_left_link_r">
    <visual>
      <origin rpy="0 0 0" xyz="0 0 0"/>
      <geometry>
        <mesh filename="package://motoman_sda20d_support/meshes/arm_link_r.STL"/>
      </geometry>
      <material name="">
        <color rgba="0.79 0.81 0.93 1"/>
      </material>
    </visual>
    <collision>
      <origin rpy="0 0 0" xyz="0 0 0"/>
      <geometry>
        <mesh filename="package://motoman_sda20d_support/meshes/arm_link_r.STL"/>
      </geometry>
    </collision>
  </link>
  <joint name="arm_left_joint_r" type="revolute">
    <origin rpy="-1.57079632679 0 1.57079632679" xyz="0.26425 0 0.0015"/>
    <parent link="arm_left_link_u"/>
    <child link="arm_left_link_r"/>
    <axis xyz="0 0 1"/>
    <limit effort="1000" lower="-3.14" upper="3.14" velocity="1.5719"/>
  </joint>
  <link name="arm_left_link_b">
    <visual>
      <origin rpy="0 0 0" xyz="0 0 0"/>
      <geometry>
        <mesh filename="package://motoman_sda20d_support/meshes/arm_link_b.STL"/>
      </geometry>
      <material name="">
        <color rgba="0.79 0.81 1 1"/>
      </material>
    </visual>
    <collision>
      <origin rpy="0 0 0" xyz="0 0 0"/>
      <geometry>
        <mesh filename="package://motoman_sda20d_support/meshes/arm_link_b.STL"/>
      </geometry>
    </collision>
  </link>
  <joint name="arm_left_joint_b" type="revolute">
    <origin rpy="3.14159265359 1.57079632679 0" xyz="0 0 -0.181"/>
    <parent link="arm_left_link_r"/>
    <child link="arm_left_link_b"/>
    <axis xyz="0 -1 0"/>
    <limit effort="1000" lower="-1.917" upper="1.917" velocity="1.74"/>
  </joint>
  <link name="arm_left_link_t">
    <visual>
      <origin rpy="0 0 0" xyz="0 0 0"/>
      <geometry>
        <mesh filename="package://motoman_sda20d_support/meshes/arm_link_t.STL"/>
      </geometry>
      <material name="">
        <color rgba="0.79 0.81 0.93 1"/>
      </material>
    </visual>
    <collision>
      <origin rpy="0 0 0" xyz="0 0 0"/>
      <geometry>
        <mesh filename="package://motoman_sda20d_support/meshes/arm_link_t.STL"/>
      </geometry>
    </collision>
  </link>
  <joint name="arm_left_joint_t" type="revolute">
    <origin rpy="3.14159265359 1.57079632679 0" xyz="0.16725 0.02775 0"/>
    <parent link="arm_left_link_b"/>
    <child link="arm_left_link_t"/>
    <axis xyz="0 0 1"/>
    <limit effort="1000" lower="-3.1383" upper="3.1383" velocity="2.0453"/>
  </joint>
  <link name="arm_right_link_s">
    <visual>
      <origin rpy="0 0 0" xyz="0 0 0"/>
      <geometry>
        <mesh filename="package://motoman_sda20d_support/meshes/arm_link_s.STL"/>
      </geometry>
      <material name="">
        <color rgba="0.79 0.81 0.93 1"/>
      </material>
    </visual>
    <collision>
      <origin rpy="0 0 0" xyz="0 0 0"/>
      <geometry>
        <mesh filename="package://motoman_sda20d_support/meshes/arm_link_s.STL"/>
      </geometry>
    </collision>
  </link>
  <joint name="arm_right_joint_s" type="revolute">
    <origin rpy="-1.57079632679 3.14159265359 0" xyz="0.15 -0.075 0.2984"/>
    <parent link="torso_link_b1"/>
    <child link="arm_right_link_s"/>
    <axis xyz="0 0 1"/>
    <limit effort="1000" lower="-3.14" upper="3.14" velocity="0.9086"/>
  </joint>
  <link name="arm_right_link_l">
    <visual>
      <origin rpy="0 0 0" xyz="0 0 0"/>
      <geometry>
        <mesh filename="package://motoman_sda20d_support/meshes/arm_link_l.STL"/>
      </geometry>
      <material name="">
        <color rgba="0.79 0.81 1 1"/>
      </material>
    </visual>
    <collision>
      <origin rpy="0 0 0" xyz="0 0 0"/>
      <geometry>
        <mesh filename="package://motoman_sda20d_support/meshes/arm_link_l.STL"/>
      </geometry>
    </collision>
  </link>
  <joint name="arm_right_joint_l" type="revolute">
    <origin rpy="-1.57079632679 1.57079632679 0" xyz="0 -0.0571 -0.3145"/>
    <parent link="arm_right_link_s"/>
    <child link="arm_right_link_l"/>
    <axis xyz="0 0 1"/>
    <limit effort="1000" lower="-1.92" upper="1.92" velocity="0.796"/>
  </joint>
  <link name="arm_right_link_e">
    <visual>
      <origin rpy="0 0 0" xyz="0 0 0"/>
      <geometry>
        <mesh filename="package://motoman_sda20d_support/meshes/arm_link_e.STL"/>
      </geometry>
      <material name="">
        <color rgba="0.79 0.81 0.93 1"/>
      </material>
    </visual>
    <collision>
      <origin rpy="0 0 0" xyz="0 0 0"/>
      <geometry>
        <mesh filename="package://motoman_sda20d_support/meshes/arm_link_e.STL"/>
      </geometry>
    </collision>
  </link>
  <joint name="arm_right_joint_e" type="revolute">
    <origin rpy="-1.57079632679 3.14159265359 1.57079632679" xyz="0.2659 0 0.04877"/>
    <parent link="arm_right_link_l"/>
    <child link="arm_right_link_e"/>
    <axis xyz="0 0 1"/>
    <limit effort="1000" lower="-2.966" upper="2.966" velocity="1.039"/>
  </joint>
  <link name="arm_right_link_u">
    <visual>
      <origin rpy="0 0 0" xyz="0 0 0"/>
      <geometry>
        <mesh filename="package://motoman_sda20d_support/meshes/arm_link_u.STL"/>
      </geometry>
      <material name="">
        <color rgba="0.79 0.81 1 1"/>
      </material>
    </visual>
    <collision>
      <origin rpy="0 0 0" xyz="0 0 0"/>
      <geometry>
        <mesh filename="package://motoman_sda20d_support/meshes/arm_link_u.STL"/>
      </geometry>
    </collision>
  </link>
  <joint name="arm_right_joint_u" type="revolute">
    <origin rpy="1.57079632679 1.57079632679 0" xyz="0 0.0494 -0.2441"/>
    <parent link="arm_right_link_e"/>
    <child link="arm_right_link_u"/>
    <axis xyz="0 0 1"/>
    <limit effort="1000" lower="-2.2689" upper="2.2689" velocity="1.188"/>
  </joint>
  <link name="arm_right_link_r">
    <visual>
      <origin rpy="0 0 0" xyz="0 0 0"/>
      <geometry>
        <mesh filename="package://motoman_sda20d_support/meshes/arm_link_r.STL"/>
      </geometry>
      <material name="">
        <color rgba="0.79 0.81 0.93 1"/>
      </material>
    </visual>
    <collision>
      <origin rpy="0 0 0" xyz="0 0 0"/>
      <geometry>
        <mesh filename="package://motoman_sda20d_support/meshes/arm_link_r.STL"/>
      </geometry>
    </collision>
  </link>
  <joint name="arm_right_joint_r" type="revolute">
    <origin rpy="-1.57079632679 0 1.57079632679" xyz="0.26425 0 0.0015"/>
    <parent link="arm_right_link_u"/>
    <child link="arm_right_link_r"/>
    <axis xyz="0 0 -1"/>
    <limit effort="1000" lower="-3.14" upper="3.14" velocity="1.5719"/>
  </joint>
  <link name="arm_right_link_b">
    <visual>
      <origin rpy="0 0 0" xyz="0 0 0"/>
      <geometry>
        <mesh filename="package://motoman_sda20d_support/meshes/arm_link_b.STL"/>
      </geometry>
      <material name="">
        <color rgba="0.79 0.81 1 1"/>
      </material>
    </visual>
    <collision>
      <origin rpy="0 0 0" xyz="0 0 0"/>
      <geometry>
        <mesh filename="package://motoman_sda20d_support/meshes/arm_link_b.STL"/>
      </geometry>
    </collision>
  </link>
  <joint name="arm_right_joint_b" type="revolute">
    <origin rpy="3.14159265359 1.57079632679 0" xyz="0 0 -0.181"/>
    <parent link="arm_right_link_r"/>
    <child link="arm_right_link_b"/>
    <axis xyz="0 1 0"/>
    <limit effort="1000" lower="-1.917" upper="1.917" velocity="1.74"/>
  </joint>
  <link name="arm_right_link_t">
    <visual>
      <origin rpy="0 0 0" xyz="0 0 0"/>
      <geometry>
        <mesh filename="package://motoman_sda20d_support/meshes/arm_link_t.STL"/>
      </geometry>
      <material name="">
        <color rgba="0.79 0.81 0.93 1"/>
      </material>
    </visual>
    <collision>
      <origin rpy="0 0 0" xyz="0 0 0"/>
      <geometry>
        <mesh filename="package://motoman_sda20d_support/meshes/arm_link_t.STL"/>
      </geometry>
    </collision>
  </link>
  <joint name="arm_right_joint_t" type="revolute">
    <origin rpy="3.14159265359 1.57079632679 0" xyz="0.16725 0.02775 0"/>
    <parent link="arm_right_link_b"/>
    <child link="arm_right_link_t"/>
    <axis xyz="0 0 -1"/>
    <limit effort="1000" lower="-3.1383" upper="3.1383" velocity="2.0453"/>
  </joint>
</robot>

